using System;
using System.Linq;
using My.Company;
using My.Company.Common;
using Xunit;

public class TestPatternDelegates
{
    [Fact]
    public void pattern_ffi_slice_delegate()
    {
        Interop.pattern_ffi_slice_delegate(delegate(Slice<byte> x0)
        {
            Assert.Equal(x0.Count, 10);
            Assert.Equal(x0[0], 0);
            Assert.Equal(x0[5], 5);

            // Test IEnumerable using LINQ
            var arr = x0.ToArray();
            Assert.Equal(arr.Length, 10);
            Assert.Equal(arr[0], 0);
            Assert.Equal(arr[5], 5);

            return x0[0];
        });
    }

    [Fact]
    public void pattern_ffi_callback_exception()
    {
        // This value will be changed to `6` before the callbacks are invoked, and
        // changed to `8` after callbacks return.
        var rval = 0;


        FFIError C1(int x, int y)
        {
            // This should see `6` here, and it does, because the function has set that value.
            Assert.Equal(rval, 6);

            // However, when we now throw we would expect .NET to unwind that exception back
            // into Rust (and therefore eventually observe rval to be `8`). When we use this
            // safe wrapper it does that, but only because we implemented special handling for
            // it for callbacks that return a FFIError.
            throw new Exception("We handled this");
        }

        void C2(int x, int y)
        {
            // This callback looks very similar. However, it does not come with special handling
            // support. When this throws, the .NET runtime will NOT(!!!) unwind back through
            // Rust but instead just return the stack up without ever calling Rust again. That means
            // in particular that any code that you would expect to run in Rust subsequent to the invocation
            // of this callback (esp. `drop` code and friends) will NOT fire, leading to unexpected
            // memory loss or worse.

            // throw new Exception("Unchecked callback which we didn't handle. Comment this out and see the test fail.");
        };

        try
        {
            Interop.pattern_callback_7_checked(C1, C2, 3, 7, out rval);
        }
        catch (Exception e)
        {
            // If everything works Rust code after invoking C1 and C2 is still executed,
            // setting this variable to `8`.
            Assert.Equal(rval, 8);
        }

    }

}